W0617 23:51:31.686000 603799 site-packages/torch/distributed/run.py:792] 
W0617 23:51:31.686000 603799 site-packages/torch/distributed/run.py:792] *****************************************
W0617 23:51:31.686000 603799 site-packages/torch/distributed/run.py:792] Setting OMP_NUM_THREADS environment variable for each process to be 1 in default, to avoid your system being overloaded, please further tune the variable for optimal performance in your application as needed. 
W0617 23:51:31.686000 603799 site-packages/torch/distributed/run.py:792] *****************************************
Traceback (most recent call last):
  File "<frozen runpy>", line 198, in _run_module_as_main
  File "<frozen runpy>", line 88, in _run_code
  File "/home/tilman.kerl/miniconda3/envs/refusal/lib/python3.11/site-packages/sparsify/__main__.py", line 197, in <module>
    run()
  File "/home/tilman.kerl/miniconda3/envs/refusal/lib/python3.11/site-packages/sparsify/__main__.py", line 146, in run
    torch.cuda.set_device(int(local_rank))
  File "/home/tilman.kerl/miniconda3/envs/refusal/lib/python3.11/site-packages/torch/cuda/__init__.py", line 476, in set_device
    torch._C._cuda_setDevice(device)
  File "/home/tilman.kerl/miniconda3/envs/refusal/lib/python3.11/site-packages/torch/cuda/__init__.py", line 319, in _lazy_init
    torch._C._cuda_init()
RuntimeError: No CUDA GPUs are available
W0617 23:52:09.047000 603799 site-packages/torch/distributed/elastic/multiprocessing/api.py:897] Sending process 603816 closing signal SIGTERM
E0617 23:52:11.516000 603799 site-packages/torch/distributed/elastic/multiprocessing/api.py:869] failed (exitcode: 1) local_rank: 1 (pid: 603817) of binary: /home/tilman.kerl/miniconda3/envs/refusal/bin/python
Traceback (most recent call last):
  File "/home/tilman.kerl/miniconda3/envs/refusal/bin/torchrun", line 8, in <module>
    sys.exit(main())
             ^^^^^^
  File "/home/tilman.kerl/miniconda3/envs/refusal/lib/python3.11/site-packages/torch/distributed/elastic/multiprocessing/errors/__init__.py", line 355, in wrapper
    return f(*args, **kwargs)
           ^^^^^^^^^^^^^^^^^^
  File "/home/tilman.kerl/miniconda3/envs/refusal/lib/python3.11/site-packages/torch/distributed/run.py", line 918, in main
    run(args)
  File "/home/tilman.kerl/miniconda3/envs/refusal/lib/python3.11/site-packages/torch/distributed/run.py", line 909, in run
    elastic_launch(
  File "/home/tilman.kerl/miniconda3/envs/refusal/lib/python3.11/site-packages/torch/distributed/launcher/api.py", line 138, in __call__
    return launch_agent(self._config, self._entrypoint, list(args))
           ^^^^^^^^^^^^^^^^^^^^^^^^^^^^^^^^^^^^^^^^^^^^^^^^^^^^^^^^
  File "/home/tilman.kerl/miniconda3/envs/refusal/lib/python3.11/site-packages/torch/distributed/launcher/api.py", line 269, in launch_agent
    raise ChildFailedError(
torch.distributed.elastic.multiprocessing.errors.ChildFailedError: 
============================================================
sparsify FAILED
------------------------------------------------------------
Failures:
  <NO_OTHER_FAILURES>
------------------------------------------------------------
Root Cause (first observed failure):
[0]:
  time      : 2025-06-17_23:52:09
  host      : a-a100-qs-7
  rank      : 1 (local_rank: 1)
  exitcode  : 1 (pid: 603817)
  error_file: <N/A>
  traceback : To enable traceback see: https://pytorch.org/docs/stable/elastic/errors.html
============================================================
