--- Starting Run 1: Expansion Factor 16 ---
W0618 00:56:58.081000 2902247 site-packages/torch/distributed/run.py:792] 
W0618 00:56:58.081000 2902247 site-packages/torch/distributed/run.py:792] *****************************************
W0618 00:56:58.081000 2902247 site-packages/torch/distributed/run.py:792] Setting OMP_NUM_THREADS environment variable for each process to be 1 in default, to avoid your system being overloaded, please further tune the variable for optimal performance in your application as needed. 
W0618 00:56:58.081000 2902247 site-packages/torch/distributed/run.py:792] *****************************************
Traceback (most recent call last):
  File "/home/tilman.kerl/miniconda3/envs/refusal/lib/python3.11/site-packages/torch/cuda/__init__.py", line 330, in _lazy_init
    queued_call()
  File "/home/tilman.kerl/miniconda3/envs/refusal/lib/python3.11/site-packages/torch/cuda/__init__.py", line 200, in _check_capability
    capability = get_device_capability(d)
                 ^^^^^^^^^^^^^^^^^^^^^^^^
  File "/home/tilman.kerl/miniconda3/envs/refusal/lib/python3.11/site-packages/torch/cuda/__init__.py", line 507, in get_device_capability
    prop = get_device_properties(device)
           ^^^^^^^^^^^^^^^^^^^^^^^^^^^^^
  File "/home/tilman.kerl/miniconda3/envs/refusal/lib/python3.11/site-packages/torch/cuda/__init__.py", line 527, in get_device_properties
    return _get_device_properties(device)  # type: ignore[name-defined]
           ^^^^^^^^^^^^^^^^^^^^^^^^^^^^^^
RuntimeError: device >= 0 && device < num_gpus INTERNAL ASSERT FAILED at "/pytorch/aten/src/ATen/cuda/CUDAContext.cpp":49, please report a bug to PyTorch. device=1, num_gpus=

The above exception was the direct cause of the following exception:

Traceback (most recent call last):
  File "<frozen runpy>", line 189, in _run_module_as_main
  File "<frozen runpy>", line 148, in _get_module_details
  File "<frozen runpy>", line 112, in _get_module_details
  File "/home/tilman.kerl/miniconda3/envs/refusal/lib/python3.11/site-packages/sparsify/__init__.py", line 4, in <module>
    from .sparse_coder import Sae, SparseCoder
  File "/home/tilman.kerl/miniconda3/envs/refusal/lib/python3.11/site-packages/sparsify/sparse_coder.py", line 37, in <module>
    class SparseCoder(nn.Module):
  File "/home/tilman.kerl/miniconda3/envs/refusal/lib/python3.11/site-packages/sparsify/sparse_coder.py", line 198, in SparseCoder
    enabled=torch.cuda.is_bf16_supported(),
            ^^^^^^^^^^^^^^^^^^^^^^^^^^^^^^
  File "/home/tilman.kerl/miniconda3/envs/refusal/lib/python3.11/site-packages/torch/cuda/__init__.py", line 143, in is_bf16_supported
    device = torch.cuda.current_device()
             ^^^^^^^^^^^^^^^^^^^^^^^^^^^
  File "/home/tilman.kerl/miniconda3/envs/refusal/lib/python3.11/site-packages/torch/cuda/__init__.py", line 971, in current_device
    _lazy_init()
  File "/home/tilman.kerl/miniconda3/envs/refusal/lib/python3.11/site-packages/torch/cuda/__init__.py", line 336, in _lazy_init
    raise DeferredCudaCallError(msg) from e
torch.cuda.DeferredCudaCallError: CUDA call failed lazily at initialization with error: device >= 0 && device < num_gpus INTERNAL ASSERT FAILED at "/pytorch/aten/src/ATen/cuda/CUDAContext.cpp":49, please report a bug to PyTorch. device=1, num_gpus=

CUDA call was originally invoked at:

  File "<frozen runpy>", line 189, in _run_module_as_main
  File "<frozen runpy>", line 148, in _get_module_details
  File "<frozen runpy>", line 112, in _get_module_details
  File "<frozen importlib._bootstrap>", line 1176, in _find_and_load
  File "<frozen importlib._bootstrap>", line 1147, in _find_and_load_unlocked
  File "<frozen importlib._bootstrap>", line 690, in _load_unlocked
  File "<frozen importlib._bootstrap_external>", line 940, in exec_module
  File "<frozen importlib._bootstrap>", line 241, in _call_with_frames_removed
  File "/home/tilman.kerl/miniconda3/envs/refusal/lib/python3.11/site-packages/sparsify/__init__.py", line 4, in <module>
    from .sparse_coder import Sae, SparseCoder
  File "<frozen importlib._bootstrap>", line 1176, in _find_and_load
  File "<frozen importlib._bootstrap>", line 1147, in _find_and_load_unlocked
  File "<frozen importlib._bootstrap>", line 690, in _load_unlocked
  File "<frozen importlib._bootstrap_external>", line 940, in exec_module
  File "<frozen importlib._bootstrap>", line 241, in _call_with_frames_removed
  File "/home/tilman.kerl/miniconda3/envs/refusal/lib/python3.11/site-packages/sparsify/sparse_coder.py", line 7, in <module>
    import torch
  File "<frozen importlib._bootstrap>", line 1176, in _find_and_load
  File "<frozen importlib._bootstrap>", line 1147, in _find_and_load_unlocked
  File "<frozen importlib._bootstrap>", line 690, in _load_unlocked
  File "<frozen importlib._bootstrap_external>", line 940, in exec_module
  File "<frozen importlib._bootstrap>", line 241, in _call_with_frames_removed
  File "/home/tilman.kerl/miniconda3/envs/refusal/lib/python3.11/site-packages/torch/__init__.py", line 2046, in <module>
    _C._initExtension(_manager_path())
  File "<frozen importlib._bootstrap>", line 1176, in _find_and_load
  File "<frozen importlib._bootstrap>", line 1147, in _find_and_load_unlocked
  File "<frozen importlib._bootstrap>", line 690, in _load_unlocked
  File "<frozen importlib._bootstrap_external>", line 940, in exec_module
  File "<frozen importlib._bootstrap>", line 241, in _call_with_frames_removed
  File "/home/tilman.kerl/miniconda3/envs/refusal/lib/python3.11/site-packages/torch/cuda/__init__.py", line 264, in <module>
    _lazy_call(_check_capability)
  File "/home/tilman.kerl/miniconda3/envs/refusal/lib/python3.11/site-packages/torch/cuda/__init__.py", line 261, in _lazy_call
    _queued_calls.append((callable, traceback.format_stack()))

Traceback (most recent call last):
  File "/home/tilman.kerl/miniconda3/envs/refusal/lib/python3.11/site-packages/torch/cuda/__init__.py", line 330, in _lazy_init
    queued_call()
  File "/home/tilman.kerl/miniconda3/envs/refusal/lib/python3.11/site-packages/torch/cuda/__init__.py", line 200, in _check_capability
    capability = get_device_capability(d)
                 ^^^^^^^^^^^^^^^^^^^^^^^^
  File "/home/tilman.kerl/miniconda3/envs/refusal/lib/python3.11/site-packages/torch/cuda/__init__.py", line 507, in get_device_capability
    prop = get_device_properties(device)
           ^^^^^^^^^^^^^^^^^^^^^^^^^^^^^
  File "/home/tilman.kerl/miniconda3/envs/refusal/lib/python3.11/site-packages/torch/cuda/__init__.py", line 527, in get_device_properties
    return _get_device_properties(device)  # type: ignore[name-defined]
           ^^^^^^^^^^^^^^^^^^^^^^^^^^^^^^
RuntimeError: device >= 0 && device < num_gpus INTERNAL ASSERT FAILED at "/pytorch/aten/src/ATen/cuda/CUDAContext.cpp":49, please report a bug to PyTorch. device=1, num_gpus=

The above exception was the direct cause of the following exception:

Traceback (most recent call last):
  File "<frozen runpy>", line 189, in _run_module_as_main
  File "<frozen runpy>", line 148, in _get_module_details
  File "<frozen runpy>", line 112, in _get_module_details
  File "/home/tilman.kerl/miniconda3/envs/refusal/lib/python3.11/site-packages/sparsify/__init__.py", line 4, in <module>
    from .sparse_coder import Sae, SparseCoder
  File "/home/tilman.kerl/miniconda3/envs/refusal/lib/python3.11/site-packages/sparsify/sparse_coder.py", line 37, in <module>
    class SparseCoder(nn.Module):
  File "/home/tilman.kerl/miniconda3/envs/refusal/lib/python3.11/site-packages/sparsify/sparse_coder.py", line 198, in SparseCoder
    enabled=torch.cuda.is_bf16_supported(),
            ^^^^^^^^^^^^^^^^^^^^^^^^^^^^^^
  File "/home/tilman.kerl/miniconda3/envs/refusal/lib/python3.11/site-packages/torch/cuda/__init__.py", line 143, in is_bf16_supported
    device = torch.cuda.current_device()
             ^^^^^^^^^^^^^^^^^^^^^^^^^^^
  File "/home/tilman.kerl/miniconda3/envs/refusal/lib/python3.11/site-packages/torch/cuda/__init__.py", line 971, in current_device
    _lazy_init()
  File "/home/tilman.kerl/miniconda3/envs/refusal/lib/python3.11/site-packages/torch/cuda/__init__.py", line 336, in _lazy_init
    raise DeferredCudaCallError(msg) from e
torch.cuda.DeferredCudaCallError: CUDA call failed lazily at initialization with error: device >= 0 && device < num_gpus INTERNAL ASSERT FAILED at "/pytorch/aten/src/ATen/cuda/CUDAContext.cpp":49, please report a bug to PyTorch. device=1, num_gpus=

CUDA call was originally invoked at:

  File "<frozen runpy>", line 189, in _run_module_as_main
  File "<frozen runpy>", line 148, in _get_module_details
  File "<frozen runpy>", line 112, in _get_module_details
  File "<frozen importlib._bootstrap>", line 1176, in _find_and_load
  File "<frozen importlib._bootstrap>", line 1147, in _find_and_load_unlocked
  File "<frozen importlib._bootstrap>", line 690, in _load_unlocked
  File "<frozen importlib._bootstrap_external>", line 940, in exec_module
  File "<frozen importlib._bootstrap>", line 241, in _call_with_frames_removed
  File "/home/tilman.kerl/miniconda3/envs/refusal/lib/python3.11/site-packages/sparsify/__init__.py", line 4, in <module>
    from .sparse_coder import Sae, SparseCoder
  File "<frozen importlib._bootstrap>", line 1176, in _find_and_load
  File "<frozen importlib._bootstrap>", line 1147, in _find_and_load_unlocked
  File "<frozen importlib._bootstrap>", line 690, in _load_unlocked
  File "<frozen importlib._bootstrap_external>", line 940, in exec_module
  File "<frozen importlib._bootstrap>", line 241, in _call_with_frames_removed
  File "/home/tilman.kerl/miniconda3/envs/refusal/lib/python3.11/site-packages/sparsify/sparse_coder.py", line 7, in <module>
    import torch
  File "<frozen importlib._bootstrap>", line 1176, in _find_and_load
  File "<frozen importlib._bootstrap>", line 1147, in _find_and_load_unlocked
  File "<frozen importlib._bootstrap>", line 690, in _load_unlocked
  File "<frozen importlib._bootstrap_external>", line 940, in exec_module
  File "<frozen importlib._bootstrap>", line 241, in _call_with_frames_removed
  File "/home/tilman.kerl/miniconda3/envs/refusal/lib/python3.11/site-packages/torch/__init__.py", line 2046, in <module>
    _C._initExtension(_manager_path())
  File "<frozen importlib._bootstrap>", line 1176, in _find_and_load
  File "<frozen importlib._bootstrap>", line 1147, in _find_and_load_unlocked
  File "<frozen importlib._bootstrap>", line 690, in _load_unlocked
  File "<frozen importlib._bootstrap_external>", line 940, in exec_module
  File "<frozen importlib._bootstrap>", line 241, in _call_with_frames_removed
  File "/home/tilman.kerl/miniconda3/envs/refusal/lib/python3.11/site-packages/torch/cuda/__init__.py", line 264, in <module>
    _lazy_call(_check_capability)
  File "/home/tilman.kerl/miniconda3/envs/refusal/lib/python3.11/site-packages/torch/cuda/__init__.py", line 261, in _lazy_call
    _queued_calls.append((callable, traceback.format_stack()))

W0618 00:57:02.397000 2902247 site-packages/torch/distributed/elastic/multiprocessing/api.py:897] Sending process 2902257 closing signal SIGTERM
E0618 00:57:02.511000 2902247 site-packages/torch/distributed/elastic/multiprocessing/api.py:869] failed (exitcode: 1) local_rank: 0 (pid: 2902256) of binary: /home/tilman.kerl/miniconda3/envs/refusal/bin/python
Traceback (most recent call last):
  File "/home/tilman.kerl/miniconda3/envs/refusal/bin/torchrun", line 8, in <module>
    sys.exit(main())
             ^^^^^^
  File "/home/tilman.kerl/miniconda3/envs/refusal/lib/python3.11/site-packages/torch/distributed/elastic/multiprocessing/errors/__init__.py", line 355, in wrapper
    return f(*args, **kwargs)
           ^^^^^^^^^^^^^^^^^^
  File "/home/tilman.kerl/miniconda3/envs/refusal/lib/python3.11/site-packages/torch/distributed/run.py", line 918, in main
    run(args)
  File "/home/tilman.kerl/miniconda3/envs/refusal/lib/python3.11/site-packages/torch/distributed/run.py", line 909, in run
    elastic_launch(
  File "/home/tilman.kerl/miniconda3/envs/refusal/lib/python3.11/site-packages/torch/distributed/launcher/api.py", line 138, in __call__
    return launch_agent(self._config, self._entrypoint, list(args))
           ^^^^^^^^^^^^^^^^^^^^^^^^^^^^^^^^^^^^^^^^^^^^^^^^^^^^^^^^
  File "/home/tilman.kerl/miniconda3/envs/refusal/lib/python3.11/site-packages/torch/distributed/launcher/api.py", line 269, in launch_agent
    raise ChildFailedError(
torch.distributed.elastic.multiprocessing.errors.ChildFailedError: 
============================================================
sparsify FAILED
------------------------------------------------------------
Failures:
  <NO_OTHER_FAILURES>
------------------------------------------------------------
Root Cause (first observed failure):
[0]:
  time      : 2025-06-18_00:57:02
  host      : a-a40-o-1
  rank      : 0 (local_rank: 0)
  exitcode  : 1 (pid: 2902256)
  error_file: <N/A>
  traceback : To enable traceback see: https://pytorch.org/docs/stable/elastic/errors.html
============================================================
